ERROR 2024-12-04 00:29:02,579 views Acesta este un mesaj de eroare.
CRITICAL 2024-12-04 00:29:02,579 views Acesta este un mesaj critic.
ERROR 2024-12-04 00:29:02,651 log Internal Server Error: /aplicatie/debug
Traceback (most recent call last):
  File "/usr/lib/python3/dist-packages/django/core/handlers/exception.py", line 55, in inner
    response = get_response(request)
               ^^^^^^^^^^^^^^^^^^^^^
  File "/usr/lib/python3/dist-packages/django/core/handlers/base.py", line 204, in _get_response
    self.check_response(response, callback)
  File "/usr/lib/python3/dist-packages/django/core/handlers/base.py", line 332, in check_response
    raise ValueError(
ValueError: The view gelaterie.views.afisare_pagina didn't return an HttpResponse object. It returned None instead.
ERROR 2024-12-04 00:29:02,652 basehttp "GET /aplicatie/debug HTTP/1.1" 500 73271
ERROR 2024-12-04 00:31:24,277 views Eroare la calcul: division by zero
ERROR 2024-12-04 00:32:35,596 views Eroare la calcul: division by zero
ERROR 2024-12-04 00:32:44,189 views Eroare la calcul: division by zero
ERROR 2024-12-04 00:37:07,812 views Eroare la calcul: division by zero
ERROR 2024-12-04 00:38:13,409 views Eroare la calcul: division by zero
ERROR 2024-12-04 00:40:44,478 log Internal Server Error: /comenzi
Traceback (most recent call last):
  File "/usr/lib/python3/dist-packages/django/core/handlers/exception.py", line 55, in inner
    response = get_response(request)
               ^^^^^^^^^^^^^^^^^^^^^
  File "/usr/lib/python3/dist-packages/django/core/handlers/base.py", line 204, in _get_response
    self.check_response(response, callback)
  File "/usr/lib/python3/dist-packages/django/core/handlers/base.py", line 332, in check_response
    raise ValueError(
ValueError: The view gelaterie.views.comenzi didn't return an HttpResponse object. It returned None instead.
ERROR 2024-12-04 00:40:44,479 basehttp "GET /comenzi HTTP/1.1" 500 73136
ERROR 2024-12-04 00:41:18,314 log Internal Server Error: /comenzi
Traceback (most recent call last):
  File "/usr/lib/python3/dist-packages/django/core/handlers/exception.py", line 55, in inner
    response = get_response(request)
               ^^^^^^^^^^^^^^^^^^^^^
  File "/usr/lib/python3/dist-packages/django/core/handlers/base.py", line 204, in _get_response
    self.check_response(response, callback)
  File "/usr/lib/python3/dist-packages/django/core/handlers/base.py", line 332, in check_response
    raise ValueError(
ValueError: The view gelaterie.views.comenzi didn't return an HttpResponse object. It returned None instead.
ERROR 2024-12-04 00:41:18,315 basehttp "GET /comenzi HTTP/1.1" 500 73273
ERROR 2024-12-04 01:11:21,149 log Internal Server Error: /aplicatie/contact
Traceback (most recent call last):
  File "/usr/lib/python3/dist-packages/django/core/handlers/exception.py", line 55, in inner
    response = get_response(request)
               ^^^^^^^^^^^^^^^^^^^^^
  File "/usr/lib/python3/dist-packages/django/core/handlers/base.py", line 197, in _get_response
    response = wrapped_callback(request, *callback_args, **callback_kwargs)
               ^^^^^^^^^^^^^^^^^^^^^^^^^^^^^^^^^^^^^^^^^^^^^^^^^^^^^^^^^^^^
  File "/home/davide/Documents/ProiectDjango/Proiect/gelaterie/views.py", line 278, in contact_view
    with open(file_path, 'w') as json_file:
         ^^^^^^^^^^^^^^^^^^^^
FileNotFoundError: [Errno 2] No such file or directory: '/home/davide/Documents/ProiectDjango/Proiect/mesaje/mesaj_1733274681.json'
ERROR 2024-12-04 01:11:21,151 basehttp "POST /aplicatie/contact HTTP/1.1" 500 77745
ERROR 2024-12-04 15:17:56,433 log Internal Server Error: /adresa
Traceback (most recent call last):
  File "/usr/lib/python3/dist-packages/django/core/handlers/exception.py", line 55, in inner
    response = get_response(request)
               ^^^^^^^^^^^^^^^^^^^^^
  File "/usr/lib/python3/dist-packages/django/core/handlers/base.py", line 197, in _get_response
    response = wrapped_callback(request, *callback_args, **callback_kwargs)
               ^^^^^^^^^^^^^^^^^^^^^^^^^^^^^^^^^^^^^^^^^^^^^^^^^^^^^^^^^^^^
  File "/home/davide/Documents/ProiectDjango/Proiect/gelaterie/views.py", line 54, in adresa
    return render(request, 'gelaterie/403.html', {
           ^^^^^^^^^^^^^^^^^^^^^^^^^^^^^^^^^^^^^^^
  File "/usr/lib/python3/dist-packages/django/shortcuts.py", line 24, in render
    content = loader.render_to_string(template_name, context, request, using=using)
              ^^^^^^^^^^^^^^^^^^^^^^^^^^^^^^^^^^^^^^^^^^^^^^^^^^^^^^^^^^^^^^^^^^^^^
  File "/usr/lib/python3/dist-packages/django/template/loader.py", line 61, in render_to_string
    template = get_template(template_name, using=using)
               ^^^^^^^^^^^^^^^^^^^^^^^^^^^^^^^^^^^^^^^^
  File "/usr/lib/python3/dist-packages/django/template/loader.py", line 19, in get_template
    raise TemplateDoesNotExist(template_name, chain=chain)
django.template.exceptions.TemplateDoesNotExist: gelaterie/403.html
ERROR 2024-12-04 15:17:56,435 basehttp "GET /adresa HTTP/1.1" 500 88031
ERROR 2024-12-04 18:30:38,262 log Internal Server Error: /aplicatie/
Traceback (most recent call last):
  File "/usr/lib/python3/dist-packages/django/core/handlers/exception.py", line 55, in inner
    response = get_response(request)
               ^^^^^^^^^^^^^^^^^^^^^
  File "/usr/lib/python3/dist-packages/django/core/handlers/base.py", line 197, in _get_response
    response = wrapped_callback(request, *callback_args, **callback_kwargs)
               ^^^^^^^^^^^^^^^^^^^^^^^^^^^^^^^^^^^^^^^^^^^^^^^^^^^^^^^^^^^^
  File "/home/davide/Documents/ProiectDjango/Proiect/gelaterie/views.py", line 317, in display_items
    return render(request, 'oferta.html', {'message': 'Reducere 50%! Profitați acum!'})
           ^^^^^^^^^^^^^^^^^^^^^^^^^^^^^^^^^^^^^^^^^^^^^^^^^^^^^^^^^^^^^^^^^^^^^^^^^^^^
  File "/usr/lib/python3/dist-packages/django/shortcuts.py", line 24, in render
    content = loader.render_to_string(template_name, context, request, using=using)
              ^^^^^^^^^^^^^^^^^^^^^^^^^^^^^^^^^^^^^^^^^^^^^^^^^^^^^^^^^^^^^^^^^^^^^
  File "/usr/lib/python3/dist-packages/django/template/loader.py", line 61, in render_to_string
    template = get_template(template_name, using=using)
               ^^^^^^^^^^^^^^^^^^^^^^^^^^^^^^^^^^^^^^^^
  File "/usr/lib/python3/dist-packages/django/template/loader.py", line 19, in get_template
    raise TemplateDoesNotExist(template_name, chain=chain)
django.template.exceptions.TemplateDoesNotExist: oferta.html
ERROR 2024-12-04 18:30:38,263 basehttp "GET /aplicatie/ HTTP/1.1" 500 93163
ERROR 2024-12-04 18:34:05,676 log Internal Server Error: /oferta
Traceback (most recent call last):
  File "/usr/lib/python3/dist-packages/django/core/handlers/exception.py", line 55, in inner
    response = get_response(request)
               ^^^^^^^^^^^^^^^^^^^^^
  File "/usr/lib/python3/dist-packages/django/core/handlers/base.py", line 197, in _get_response
    response = wrapped_callback(request, *callback_args, **callback_kwargs)
               ^^^^^^^^^^^^^^^^^^^^^^^^^^^^^^^^^^^^^^^^^^^^^^^^^^^^^^^^^^^^
  File "/home/davide/Documents/ProiectDjango/Proiect/gelaterie/views.py", line 912, in oferta
    return render(request, 'gelaterie/oferta.html', {'message': 'Reducere 50%! Profitați acum!'})
           ^^^^^^^^^^^^^^^^^^^^^^^^^^^^^^^^^^^^^^^^^^^^^^^^^^^^^^^^^^^^^^^^^^^^^^^^^^^^^^^^^^^^^^
  File "/usr/lib/python3/dist-packages/django/shortcuts.py", line 24, in render
    content = loader.render_to_string(template_name, context, request, using=using)
              ^^^^^^^^^^^^^^^^^^^^^^^^^^^^^^^^^^^^^^^^^^^^^^^^^^^^^^^^^^^^^^^^^^^^^
  File "/usr/lib/python3/dist-packages/django/template/loader.py", line 61, in render_to_string
    template = get_template(template_name, using=using)
               ^^^^^^^^^^^^^^^^^^^^^^^^^^^^^^^^^^^^^^^^
  File "/usr/lib/python3/dist-packages/django/template/loader.py", line 19, in get_template
    raise TemplateDoesNotExist(template_name, chain=chain)
django.template.exceptions.TemplateDoesNotExist: gelaterie/oferta.html
ERROR 2024-12-04 18:34:05,677 basehttp "GET /oferta HTTP/1.1" 500 87654
ERROR 2024-12-05 10:52:39,834 log Internal Server Error: /sitemap.xml
Traceback (most recent call last):
  File "/usr/lib/python3/dist-packages/django/core/handlers/exception.py", line 55, in inner
    response = get_response(request)
               ^^^^^^^^^^^^^^^^^^^^^
  File "/usr/lib/python3/dist-packages/django/core/handlers/base.py", line 197, in _get_response
    response = wrapped_callback(request, *callback_args, **callback_kwargs)
               ^^^^^^^^^^^^^^^^^^^^^^^^^^^^^^^^^^^^^^^^^^^^^^^^^^^^^^^^^^^^
  File "/usr/lib/python3/dist-packages/django/contrib/sitemaps/views.py", line 34, in inner
    response = func(request, *args, **kwargs)
               ^^^^^^^^^^^^^^^^^^^^^^^^^^^^^^
  File "/usr/lib/python3/dist-packages/django/contrib/sitemaps/views.py", line 128, in sitemap
    urls.extend(site.get_urls(page=page, site=req_site, protocol=req_protocol))
                ^^^^^^^^^^^^^^^^^^^^^^^^^^^^^^^^^^^^^^^^^^^^^^^^^^^^^^^^^^^^^^
  File "/usr/lib/python3/dist-packages/django/contrib/sitemaps/__init__.py", line 167, in get_urls
    return self._urls(page, protocol, domain)
           ^^^^^^^^^^^^^^^^^^^^^^^^^^^^^^^^^^
  File "/usr/lib/python3/dist-packages/django/contrib/sitemaps/__init__.py", line 187, in _urls
    loc = f"{protocol}://{domain}{self._location(item)}"
                                  ^^^^^^^^^^^^^^^^^^^^
  File "/usr/lib/python3/dist-packages/django/contrib/sitemaps/__init__.py", line 122, in _location
    return self._get("location", item)
           ^^^^^^^^^^^^^^^^^^^^^^^^^^^
  File "/usr/lib/python3/dist-packages/django/contrib/sitemaps/__init__.py", line 92, in _get
    return attr(item)
           ^^^^^^^^^^
  File "/usr/lib/python3/dist-packages/django/contrib/sitemaps/__init__.py", line 132, in location
    return item.get_absolute_url()
           ^^^^^^^^^^^^^^^^^^^^^
AttributeError: 'Sponsor' object has no attribute 'get_absolute_url'
ERROR 2024-12-05 10:52:39,842 basehttp "GET /sitemap.xml HTTP/1.1" 500 103451
ERROR 2024-12-05 10:53:16,025 log Internal Server Error: /sitemap.xml
Traceback (most recent call last):
  File "/usr/lib/python3/dist-packages/django/core/handlers/exception.py", line 55, in inner
    response = get_response(request)
               ^^^^^^^^^^^^^^^^^^^^^
  File "/usr/lib/python3/dist-packages/django/core/handlers/base.py", line 197, in _get_response
    response = wrapped_callback(request, *callback_args, **callback_kwargs)
               ^^^^^^^^^^^^^^^^^^^^^^^^^^^^^^^^^^^^^^^^^^^^^^^^^^^^^^^^^^^^
  File "/usr/lib/python3/dist-packages/django/contrib/sitemaps/views.py", line 34, in inner
    response = func(request, *args, **kwargs)
               ^^^^^^^^^^^^^^^^^^^^^^^^^^^^^^
  File "/usr/lib/python3/dist-packages/django/contrib/sitemaps/views.py", line 128, in sitemap
    urls.extend(site.get_urls(page=page, site=req_site, protocol=req_protocol))
                ^^^^^^^^^^^^^^^^^^^^^^^^^^^^^^^^^^^^^^^^^^^^^^^^^^^^^^^^^^^^^^
  File "/usr/lib/python3/dist-packages/django/contrib/sitemaps/__init__.py", line 167, in get_urls
    return self._urls(page, protocol, domain)
           ^^^^^^^^^^^^^^^^^^^^^^^^^^^^^^^^^^
  File "/usr/lib/python3/dist-packages/django/contrib/sitemaps/__init__.py", line 187, in _urls
    loc = f"{protocol}://{domain}{self._location(item)}"
                                  ^^^^^^^^^^^^^^^^^^^^
  File "/usr/lib/python3/dist-packages/django/contrib/sitemaps/__init__.py", line 122, in _location
    return self._get("location", item)
           ^^^^^^^^^^^^^^^^^^^^^^^^^^^
  File "/usr/lib/python3/dist-packages/django/contrib/sitemaps/__init__.py", line 92, in _get
    return attr(item)
           ^^^^^^^^^^
  File "/usr/lib/python3/dist-packages/django/contrib/sitemaps/__init__.py", line 132, in location
    return item.get_absolute_url()
           ^^^^^^^^^^^^^^^^^^^^^
AttributeError: 'Sponsor' object has no attribute 'get_absolute_url'
ERROR 2024-12-05 10:53:16,031 basehttp "GET /sitemap.xml HTTP/1.1" 500 103451
ERROR 2024-12-05 10:55:14,628 log Internal Server Error: /sitemap.xml
Traceback (most recent call last):
  File "/usr/lib/python3/dist-packages/django/core/handlers/exception.py", line 55, in inner
    response = get_response(request)
               ^^^^^^^^^^^^^^^^^^^^^
  File "/usr/lib/python3/dist-packages/django/core/handlers/base.py", line 197, in _get_response
    response = wrapped_callback(request, *callback_args, **callback_kwargs)
               ^^^^^^^^^^^^^^^^^^^^^^^^^^^^^^^^^^^^^^^^^^^^^^^^^^^^^^^^^^^^
  File "/usr/lib/python3/dist-packages/django/contrib/sitemaps/views.py", line 34, in inner
    response = func(request, *args, **kwargs)
               ^^^^^^^^^^^^^^^^^^^^^^^^^^^^^^
  File "/usr/lib/python3/dist-packages/django/contrib/sitemaps/views.py", line 128, in sitemap
    urls.extend(site.get_urls(page=page, site=req_site, protocol=req_protocol))
                ^^^^^^^^^^^^^^^^^^^^^^^^^^^^^^^^^^^^^^^^^^^^^^^^^^^^^^^^^^^^^^
  File "/usr/lib/python3/dist-packages/django/contrib/sitemaps/__init__.py", line 167, in get_urls
    return self._urls(page, protocol, domain)
           ^^^^^^^^^^^^^^^^^^^^^^^^^^^^^^^^^^
  File "/usr/lib/python3/dist-packages/django/contrib/sitemaps/__init__.py", line 187, in _urls
    loc = f"{protocol}://{domain}{self._location(item)}"
                                  ^^^^^^^^^^^^^^^^^^^^
  File "/usr/lib/python3/dist-packages/django/contrib/sitemaps/__init__.py", line 122, in _location
    return self._get("location", item)
           ^^^^^^^^^^^^^^^^^^^^^^^^^^^
  File "/usr/lib/python3/dist-packages/django/contrib/sitemaps/__init__.py", line 92, in _get
    return attr(item)
           ^^^^^^^^^^
  File "/usr/lib/python3/dist-packages/django/contrib/sitemaps/__init__.py", line 132, in location
    return item.get_absolute_url()
           ^^^^^^^^^^^^^^^^^^^^^
AttributeError: 'Sponsor' object has no attribute 'get_absolute_url'
ERROR 2024-12-05 10:55:14,634 basehttp "GET /sitemap.xml HTTP/1.1" 500 103588
ERROR 2024-12-05 10:55:15,573 log Internal Server Error: /sitemap.xml
Traceback (most recent call last):
  File "/usr/lib/python3/dist-packages/django/core/handlers/exception.py", line 55, in inner
    response = get_response(request)
               ^^^^^^^^^^^^^^^^^^^^^
  File "/usr/lib/python3/dist-packages/django/core/handlers/base.py", line 197, in _get_response
    response = wrapped_callback(request, *callback_args, **callback_kwargs)
               ^^^^^^^^^^^^^^^^^^^^^^^^^^^^^^^^^^^^^^^^^^^^^^^^^^^^^^^^^^^^
  File "/usr/lib/python3/dist-packages/django/contrib/sitemaps/views.py", line 34, in inner
    response = func(request, *args, **kwargs)
               ^^^^^^^^^^^^^^^^^^^^^^^^^^^^^^
  File "/usr/lib/python3/dist-packages/django/contrib/sitemaps/views.py", line 128, in sitemap
    urls.extend(site.get_urls(page=page, site=req_site, protocol=req_protocol))
                ^^^^^^^^^^^^^^^^^^^^^^^^^^^^^^^^^^^^^^^^^^^^^^^^^^^^^^^^^^^^^^
  File "/usr/lib/python3/dist-packages/django/contrib/sitemaps/__init__.py", line 167, in get_urls
    return self._urls(page, protocol, domain)
           ^^^^^^^^^^^^^^^^^^^^^^^^^^^^^^^^^^
  File "/usr/lib/python3/dist-packages/django/contrib/sitemaps/__init__.py", line 187, in _urls
    loc = f"{protocol}://{domain}{self._location(item)}"
                                  ^^^^^^^^^^^^^^^^^^^^
  File "/usr/lib/python3/dist-packages/django/contrib/sitemaps/__init__.py", line 122, in _location
    return self._get("location", item)
           ^^^^^^^^^^^^^^^^^^^^^^^^^^^
  File "/usr/lib/python3/dist-packages/django/contrib/sitemaps/__init__.py", line 92, in _get
    return attr(item)
           ^^^^^^^^^^
  File "/usr/lib/python3/dist-packages/django/contrib/sitemaps/__init__.py", line 132, in location
    return item.get_absolute_url()
           ^^^^^^^^^^^^^^^^^^^^^
AttributeError: 'Sponsor' object has no attribute 'get_absolute_url'
ERROR 2024-12-05 10:55:15,585 basehttp "GET /sitemap.xml HTTP/1.1" 500 103588
ERROR 2024-12-05 10:55:16,408 log Internal Server Error: /sitemap.xml
Traceback (most recent call last):
  File "/usr/lib/python3/dist-packages/django/core/handlers/exception.py", line 55, in inner
    response = get_response(request)
               ^^^^^^^^^^^^^^^^^^^^^
  File "/usr/lib/python3/dist-packages/django/core/handlers/base.py", line 197, in _get_response
    response = wrapped_callback(request, *callback_args, **callback_kwargs)
               ^^^^^^^^^^^^^^^^^^^^^^^^^^^^^^^^^^^^^^^^^^^^^^^^^^^^^^^^^^^^
  File "/usr/lib/python3/dist-packages/django/contrib/sitemaps/views.py", line 34, in inner
    response = func(request, *args, **kwargs)
               ^^^^^^^^^^^^^^^^^^^^^^^^^^^^^^
  File "/usr/lib/python3/dist-packages/django/contrib/sitemaps/views.py", line 128, in sitemap
    urls.extend(site.get_urls(page=page, site=req_site, protocol=req_protocol))
                ^^^^^^^^^^^^^^^^^^^^^^^^^^^^^^^^^^^^^^^^^^^^^^^^^^^^^^^^^^^^^^
  File "/usr/lib/python3/dist-packages/django/contrib/sitemaps/__init__.py", line 167, in get_urls
    return self._urls(page, protocol, domain)
           ^^^^^^^^^^^^^^^^^^^^^^^^^^^^^^^^^^
  File "/usr/lib/python3/dist-packages/django/contrib/sitemaps/__init__.py", line 187, in _urls
    loc = f"{protocol}://{domain}{self._location(item)}"
                                  ^^^^^^^^^^^^^^^^^^^^
  File "/usr/lib/python3/dist-packages/django/contrib/sitemaps/__init__.py", line 122, in _location
    return self._get("location", item)
           ^^^^^^^^^^^^^^^^^^^^^^^^^^^
  File "/usr/lib/python3/dist-packages/django/contrib/sitemaps/__init__.py", line 92, in _get
    return attr(item)
           ^^^^^^^^^^
  File "/usr/lib/python3/dist-packages/django/contrib/sitemaps/__init__.py", line 132, in location
    return item.get_absolute_url()
           ^^^^^^^^^^^^^^^^^^^^^
AttributeError: 'Sponsor' object has no attribute 'get_absolute_url'
ERROR 2024-12-05 10:55:16,419 basehttp "GET /sitemap.xml HTTP/1.1" 500 103588
ERROR 2024-12-05 11:01:33,392 log Internal Server Error: /sitemap.xml
Traceback (most recent call last):
  File "/usr/lib/python3/dist-packages/django/core/handlers/exception.py", line 55, in inner
    response = get_response(request)
               ^^^^^^^^^^^^^^^^^^^^^
  File "/usr/lib/python3/dist-packages/django/core/handlers/base.py", line 197, in _get_response
    response = wrapped_callback(request, *callback_args, **callback_kwargs)
               ^^^^^^^^^^^^^^^^^^^^^^^^^^^^^^^^^^^^^^^^^^^^^^^^^^^^^^^^^^^^
  File "/usr/lib/python3/dist-packages/django/contrib/sitemaps/views.py", line 34, in inner
    response = func(request, *args, **kwargs)
               ^^^^^^^^^^^^^^^^^^^^^^^^^^^^^^
  File "/usr/lib/python3/dist-packages/django/contrib/sitemaps/views.py", line 128, in sitemap
    urls.extend(site.get_urls(page=page, site=req_site, protocol=req_protocol))
                ^^^^^^^^^^^^^^^^^^^^^^^^^^^^^^^^^^^^^^^^^^^^^^^^^^^^^^^^^^^^^^
  File "/usr/lib/python3/dist-packages/django/contrib/sitemaps/__init__.py", line 167, in get_urls
    return self._urls(page, protocol, domain)
           ^^^^^^^^^^^^^^^^^^^^^^^^^^^^^^^^^^
  File "/usr/lib/python3/dist-packages/django/contrib/sitemaps/__init__.py", line 187, in _urls
    loc = f"{protocol}://{domain}{self._location(item)}"
                                  ^^^^^^^^^^^^^^^^^^^^
  File "/usr/lib/python3/dist-packages/django/contrib/sitemaps/__init__.py", line 122, in _location
    return self._get("location", item)
           ^^^^^^^^^^^^^^^^^^^^^^^^^^^
  File "/usr/lib/python3/dist-packages/django/contrib/sitemaps/__init__.py", line 92, in _get
    return attr(item)
           ^^^^^^^^^^
  File "/usr/lib/python3/dist-packages/django/contrib/sitemaps/__init__.py", line 132, in location
    return item.get_absolute_url()
           ^^^^^^^^^^^^^^^^^^^^^
AttributeError: 'Sponsor' object has no attribute 'get_absolute_url'
ERROR 2024-12-05 11:01:33,399 basehttp "GET /sitemap.xml HTTP/1.1" 500 102904
ERROR 2024-12-05 11:01:34,347 log Internal Server Error: /sitemap.xml
Traceback (most recent call last):
  File "/usr/lib/python3/dist-packages/django/core/handlers/exception.py", line 55, in inner
    response = get_response(request)
               ^^^^^^^^^^^^^^^^^^^^^
  File "/usr/lib/python3/dist-packages/django/core/handlers/base.py", line 197, in _get_response
    response = wrapped_callback(request, *callback_args, **callback_kwargs)
               ^^^^^^^^^^^^^^^^^^^^^^^^^^^^^^^^^^^^^^^^^^^^^^^^^^^^^^^^^^^^
  File "/usr/lib/python3/dist-packages/django/contrib/sitemaps/views.py", line 34, in inner
    response = func(request, *args, **kwargs)
               ^^^^^^^^^^^^^^^^^^^^^^^^^^^^^^
  File "/usr/lib/python3/dist-packages/django/contrib/sitemaps/views.py", line 128, in sitemap
    urls.extend(site.get_urls(page=page, site=req_site, protocol=req_protocol))
                ^^^^^^^^^^^^^^^^^^^^^^^^^^^^^^^^^^^^^^^^^^^^^^^^^^^^^^^^^^^^^^
  File "/usr/lib/python3/dist-packages/django/contrib/sitemaps/__init__.py", line 167, in get_urls
    return self._urls(page, protocol, domain)
           ^^^^^^^^^^^^^^^^^^^^^^^^^^^^^^^^^^
  File "/usr/lib/python3/dist-packages/django/contrib/sitemaps/__init__.py", line 187, in _urls
    loc = f"{protocol}://{domain}{self._location(item)}"
                                  ^^^^^^^^^^^^^^^^^^^^
  File "/usr/lib/python3/dist-packages/django/contrib/sitemaps/__init__.py", line 122, in _location
    return self._get("location", item)
           ^^^^^^^^^^^^^^^^^^^^^^^^^^^
  File "/usr/lib/python3/dist-packages/django/contrib/sitemaps/__init__.py", line 92, in _get
    return attr(item)
           ^^^^^^^^^^
  File "/usr/lib/python3/dist-packages/django/contrib/sitemaps/__init__.py", line 132, in location
    return item.get_absolute_url()
           ^^^^^^^^^^^^^^^^^^^^^
AttributeError: 'Sponsor' object has no attribute 'get_absolute_url'
ERROR 2024-12-05 11:01:34,358 basehttp "GET /sitemap.xml HTTP/1.1" 500 102904
ERROR 2024-12-05 11:01:46,564 log Internal Server Error: /sitemap.xml
Traceback (most recent call last):
  File "/usr/lib/python3/dist-packages/django/core/handlers/exception.py", line 55, in inner
    response = get_response(request)
               ^^^^^^^^^^^^^^^^^^^^^
  File "/usr/lib/python3/dist-packages/django/core/handlers/base.py", line 197, in _get_response
    response = wrapped_callback(request, *callback_args, **callback_kwargs)
               ^^^^^^^^^^^^^^^^^^^^^^^^^^^^^^^^^^^^^^^^^^^^^^^^^^^^^^^^^^^^
  File "/usr/lib/python3/dist-packages/django/contrib/sitemaps/views.py", line 34, in inner
    response = func(request, *args, **kwargs)
               ^^^^^^^^^^^^^^^^^^^^^^^^^^^^^^
  File "/usr/lib/python3/dist-packages/django/contrib/sitemaps/views.py", line 128, in sitemap
    urls.extend(site.get_urls(page=page, site=req_site, protocol=req_protocol))
                ^^^^^^^^^^^^^^^^^^^^^^^^^^^^^^^^^^^^^^^^^^^^^^^^^^^^^^^^^^^^^^
  File "/usr/lib/python3/dist-packages/django/contrib/sitemaps/__init__.py", line 167, in get_urls
    return self._urls(page, protocol, domain)
           ^^^^^^^^^^^^^^^^^^^^^^^^^^^^^^^^^^
  File "/usr/lib/python3/dist-packages/django/contrib/sitemaps/__init__.py", line 187, in _urls
    loc = f"{protocol}://{domain}{self._location(item)}"
                                  ^^^^^^^^^^^^^^^^^^^^
  File "/usr/lib/python3/dist-packages/django/contrib/sitemaps/__init__.py", line 122, in _location
    return self._get("location", item)
           ^^^^^^^^^^^^^^^^^^^^^^^^^^^
  File "/usr/lib/python3/dist-packages/django/contrib/sitemaps/__init__.py", line 92, in _get
    return attr(item)
           ^^^^^^^^^^
  File "/usr/lib/python3/dist-packages/django/contrib/sitemaps/__init__.py", line 132, in location
    return item.get_absolute_url()
           ^^^^^^^^^^^^^^^^^^^^^
AttributeError: 'Sponsor' object has no attribute 'get_absolute_url'
ERROR 2024-12-05 11:01:46,570 basehttp "GET /sitemap.xml HTTP/1.1" 500 102767
ERROR 2024-12-05 11:06:55,836 log Internal Server Error: /sitemap.xml
Traceback (most recent call last):
  File "/usr/lib/python3/dist-packages/django/core/handlers/exception.py", line 55, in inner
    response = get_response(request)
               ^^^^^^^^^^^^^^^^^^^^^
  File "/usr/lib/python3/dist-packages/django/core/handlers/base.py", line 197, in _get_response
    response = wrapped_callback(request, *callback_args, **callback_kwargs)
               ^^^^^^^^^^^^^^^^^^^^^^^^^^^^^^^^^^^^^^^^^^^^^^^^^^^^^^^^^^^^
  File "/usr/lib/python3/dist-packages/django/contrib/sitemaps/views.py", line 34, in inner
    response = func(request, *args, **kwargs)
               ^^^^^^^^^^^^^^^^^^^^^^^^^^^^^^
  File "/usr/lib/python3/dist-packages/django/contrib/sitemaps/views.py", line 128, in sitemap
    urls.extend(site.get_urls(page=page, site=req_site, protocol=req_protocol))
                ^^^^^^^^^^^^^^^^^^^^^^^^^^^^^^^^^^^^^^^^^^^^^^^^^^^^^^^^^^^^^^
  File "/usr/lib/python3/dist-packages/django/contrib/sitemaps/__init__.py", line 167, in get_urls
    return self._urls(page, protocol, domain)
           ^^^^^^^^^^^^^^^^^^^^^^^^^^^^^^^^^^
  File "/usr/lib/python3/dist-packages/django/contrib/sitemaps/__init__.py", line 187, in _urls
    loc = f"{protocol}://{domain}{self._location(item)}"
                                  ^^^^^^^^^^^^^^^^^^^^
  File "/usr/lib/python3/dist-packages/django/contrib/sitemaps/__init__.py", line 122, in _location
    return self._get("location", item)
           ^^^^^^^^^^^^^^^^^^^^^^^^^^^
  File "/usr/lib/python3/dist-packages/django/contrib/sitemaps/__init__.py", line 92, in _get
    return attr(item)
           ^^^^^^^^^^
  File "/home/davide/Documents/ProiectDjango/Proiect/gelaterie/sitemaps.py", line 16, in location
    return reverse('sponsor_list')
         ^^^^^^^^^^^^^^^^^^^^^^^
  File "/usr/lib/python3/dist-packages/django/urls/base.py", line 88, in reverse
    return resolver._reverse_with_prefix(view, prefix, *args, **kwargs)
           ^^^^^^^^^^^^^^^^^^^^^^^^^^^^^^^^^^^^^^^^^^^^^^^^^^^^^^^^^^^^
  File "/usr/lib/python3/dist-packages/django/urls/resolvers.py", line 828, in _reverse_with_prefix
    raise NoReverseMatch(msg)
django.urls.exceptions.NoReverseMatch: Reverse for 'sponsor_list' not found. 'sponsor_list' is not a valid view function or pattern name.
ERROR 2024-12-05 11:06:55,841 basehttp "GET /sitemap.xml HTTP/1.1" 500 113763
ERROR 2024-12-05 11:06:57,943 log Internal Server Error: /sitemap.xml
Traceback (most recent call last):
  File "/usr/lib/python3/dist-packages/django/core/handlers/exception.py", line 55, in inner
    response = get_response(request)
               ^^^^^^^^^^^^^^^^^^^^^
  File "/usr/lib/python3/dist-packages/django/core/handlers/base.py", line 197, in _get_response
    response = wrapped_callback(request, *callback_args, **callback_kwargs)
               ^^^^^^^^^^^^^^^^^^^^^^^^^^^^^^^^^^^^^^^^^^^^^^^^^^^^^^^^^^^^
  File "/usr/lib/python3/dist-packages/django/contrib/sitemaps/views.py", line 34, in inner
    response = func(request, *args, **kwargs)
               ^^^^^^^^^^^^^^^^^^^^^^^^^^^^^^
  File "/usr/lib/python3/dist-packages/django/contrib/sitemaps/views.py", line 128, in sitemap
    urls.extend(site.get_urls(page=page, site=req_site, protocol=req_protocol))
                ^^^^^^^^^^^^^^^^^^^^^^^^^^^^^^^^^^^^^^^^^^^^^^^^^^^^^^^^^^^^^^
  File "/usr/lib/python3/dist-packages/django/contrib/sitemaps/__init__.py", line 167, in get_urls
    return self._urls(page, protocol, domain)
           ^^^^^^^^^^^^^^^^^^^^^^^^^^^^^^^^^^
  File "/usr/lib/python3/dist-packages/django/contrib/sitemaps/__init__.py", line 187, in _urls
    loc = f"{protocol}://{domain}{self._location(item)}"
                                  ^^^^^^^^^^^^^^^^^^^^
  File "/usr/lib/python3/dist-packages/django/contrib/sitemaps/__init__.py", line 122, in _location
    return self._get("location", item)
           ^^^^^^^^^^^^^^^^^^^^^^^^^^^
  File "/usr/lib/python3/dist-packages/django/contrib/sitemaps/__init__.py", line 92, in _get
    return attr(item)
           ^^^^^^^^^^
  File "/home/davide/Documents/ProiectDjango/Proiect/gelaterie/sitemaps.py", line 16, in location
    return reverse('sponsor_list')
         ^^^^^^^^^^^^^^^^^^^^^^^
  File "/usr/lib/python3/dist-packages/django/urls/base.py", line 88, in reverse
    return resolver._reverse_with_prefix(view, prefix, *args, **kwargs)
           ^^^^^^^^^^^^^^^^^^^^^^^^^^^^^^^^^^^^^^^^^^^^^^^^^^^^^^^^^^^^
  File "/usr/lib/python3/dist-packages/django/urls/resolvers.py", line 828, in _reverse_with_prefix
    raise NoReverseMatch(msg)
django.urls.exceptions.NoReverseMatch: Reverse for 'sponsor_list' not found. 'sponsor_list' is not a valid view function or pattern name.
ERROR 2024-12-05 11:06:57,947 basehttp "GET /sitemap.xml HTTP/1.1" 500 113763
